Workbook

Sheet HR Dashboard
A1: 🏢 HR ANALYTICS DASHBOARD | FY 2024-25
A2: Last Refreshed: June 2025 | Data Sources: ATS · HRMS · Exit Records | For Internal HR Use Only
A4: 📌 SECTION A - RECRUITMENT PIPELINE SUMMARY
A5: Total Applications | D5: Positions Filled | G5: Rejections | J5: Open Positions | M5: Avg. Days to Close
A6: ='Recruitment Pipeline'!B27 -> 20 | D6: ='Recruitment Pipeline'!D27 -> 5 | G6: ='Recruitment Pipeline'!F27 -> 3 | J6: ='Recruitment Pipeline'!H27 -> 11 | M6: ='Recruitment Pipeline'!J27 -> 24.333333
A8: # | D8: # | G8: # | J8: # | M8: (days)
A10: Pipeline Stage Breakdown - Candidates by Stage
A11: Stage | B11: Count | C11: % of Total | D11: Notes / Action Required
A12: Screening | B12: 2 | C12: 0.1 | D12: Initial shortlist in progress
A13: Technical Round | B13: 3 | C13: 0.15 | D13: Assignments sent to 3 candidates
A14: HR Interview | B14: 2 | C14: 0.1 | D14: Scheduled for next week
A15: Final Round | B15: 2 | C15: 0.1 | D15: 2 candidates - decision pending
A16: Offer Extended | B16: 2 | C16: 0.1 | D16: Awaiting candidate response
A17: Hired | B17: 6 | C17: 0.3 | D17: Target: 15 hires per quarter
A18: Rejected | B18: 4 | C18: 0.2 | D18: Primarily tech screen rejections
A19: Withdrawn | B19: 1 | C19: 0.05 | D19: Counter-offer cases
A22: 📌 SECTION B - ONBOARDING STATUS SUMMARY
A23: Total Onboarded | D23: Fully Complete | G23: In Progress | J23: Not Started | M23: Completion Rate
A24: ='Onboarding Tracker'!B22 -> 15 | D24: ='Onboarding Tracker'!D22 -> 7 | G24: ='Onboarding Tracker'!F22 -> 7 | J24: ='Onboarding Tracker'!H22 -> 1 | M24: ='Onboarding Tracker'!J22 -> 0.46666667
A26: (count) | D26: (count) | G26: (count) | J26: (count) | M26: (rate)
A28: Onboarding Checklist Completion - % Employees with Task Complete
A29: Onboarding Task | B29: Completed (of 15) | C29: Completion % | D29: Status
A30: IT Setup | B30: 15 | C30: 1 | D30: ✅ On Track
A31: ID Card & Access | B31: 15 | C31: 1 | D31: ✅ On Track
A32: HR Induction | B32: 15 | C32: 1 | D32: ✅ On Track
A33: Policy Orientation | B33: 15 | C33: 1 | D33: ✅ On Track
A34: Tool Training | B34: 14 | C34: 0.93333333 | D34: ✅ On Track
A35: 30-Day Check-in | B35: 14 | C35: 0.93333333 | D35: ✅ On Track
A36: 60-Day Check-in | B36: 10 | C36: 0.66666667 | D36: 🔄 In Progress
A37: 90-Day Check-in | B37: 6 | C37: 0.4 | D37: 🔄 In Progress
A40: 📌 SECTION C - ATTRITION & EXIT SUMMARY
A41: Total Exits (FY) | D41: Voluntary | G41: Involuntary | J41: Avg. Tenure | M41: Exit Int. Done
A42: ='Attrition Data'!B25 -> 18 | D42: ='Attrition Data'!D25 -> 14 | G42: ='Attrition Data'!F25 -> 4 | J42: ='Attrition Data'!H25 -> 29.444444 | M42: ='Attrition Data'!J25 -> 15
A44: (#) | D44: (#) | G44: (#) | J44: (months) | M44: (#)
A46: Attrition by Department & Primary Exit Reason
A47: Department | B47: Exits | C47: % of Total | D47: Top Reason
A48: Engineering | B48: 6 | C48: 0.28571429 | D48: Better Compensation / Growth
A49: Analytics | B49: 3 | C49: 0.14285714 | D49: Relocation / Better Opportunity
A50: Infrastructure | B50: 3 | C50: 0.14285714 | D50: Better Compensation / Restructuring
A51: Sales | B51: 2 | C51: 0.095238095 | D51: Career Change / Targets
...

Sheet Recruitment Pipeline
A1: RECRUITMENT PIPELINE TRACKER - FY 2024-25 | TechNova Solutions Pvt. Ltd.
A2: 📋 Source: Applicant Tracking System (ATS) + Recruiter Sheets | Updated: June 2025
A3: Candidate ID | B3: Candidate Name | C3: Role / Position | D3: Department | E3: Source | F3: Date Applied | G3: Current Stage | H3: Interviewer / Owner | I3: Interview Date | J3: Offer Date | K3: Date Closed | L3: Days to Close | M3: Status | N3: Notes
A4: REC001 | B4: Arjun Mehta | C4: Senior Backend Engineer | D4: Engineering | E4: LinkedIn | F4: 45662 | G4: Hired | H4: Priya Sharma | I4: 45672 | J4: 45682 | K4: 45689 | L4: 27 | M4: Closed | N4: Joined Feb 1
A5: REC002 | B5: Sneha Rao | C5: Data Analyst | D5: Analytics | E5: Naukri | F5: 45665 | G5: Hired | H5: Rahul Nair | I5: 45677 | J5: 45687 | K5: 45698 | L5: 33 | M5: Closed | N5: Strong SQL skills
A6: REC003 | B6: Vikram Iyer | C6: DevOps Engineer | D6: Infrastructure | E6: Referral (Internal) | F6: 45667 | G6: Rejected | H6: Anil Kumar | I6: 45679 | K6: 45693 | L6: 26 | M6: Closed | N6: Failed system design
A7: REC004 | B7: Pooja Krishnan | C7: Product Manager | D7: Product | E7: LinkedIn | F7: 45672 | G7: Final Round | H7: Deepa Menon | I7: 45698 | L7: =IFERROR(K7-F7,"-") -> -45672 | M7: In Progress | N7: Strong candidate
A8: REC005 | B8: Ravi Gupta | C8: QA Engineer | D8: Quality Assurance | E8: Indeed | F8: 45675 | G8: Hired | H8: Karan Malhotra | I8: 45685 | J8: 45693 | K8: 45703 | L8: 28 | M8: Closed | N8: Automation expertise
A9: REC006 | B9: Ananya Singh | C9: UX Designer | D9: Design | E9: Dribbble | F9: 45677 | G9: Offer Extended | H9: Sunita Patel | I9: 45690 | J9: 45708 | L9: =IFERROR(K9-F9,"-") -> -45677 | M9: In Progress | N9: Portfolio impressive
A10: REC007 | B10: Karthik Suresh | C10: Cloud Architect | D10: Infrastructure | E10: LinkedIn | F10: 45679 | G10: Technical Round | H10: Anil Kumar | I10: 45693 | L10: =IFERROR(K10-F10,"-") -> -45679 | M10: In Progress | N10: AWS certified
A11: REC008 | B11: Meera Pillai | C11: HR Business Partner | D11: Human Resources | E11: Naukri | F11: 45682 | G11: Screening | H11: Divya Nambiar | L11: =IFERROR(K11-F11,"-") -> -45682 | M11: In Progress | N11: Screening scheduled Feb 28
A12: REC009 | B12: Suresh Babu | C12: Mobile Developer (iOS) | D12: Engineering | E12: AngelList | F12: 45685 | G12: Rejected | H12: Priya Sharma | I12: 45696 | K12: 45703 | L12: 18 | M12: Closed | N12: No SwiftUI exp.
A13: REC010 | B13: Lakshmi Nair | C13: Finance Analyst | D13: Finance | E13: Referral (External) | F13: 45689 | G13: HR Interview | H13: Rahul Nair | I13: 45703 | L13: =IFERROR(K13-F13,"-") -> -45689 | M13: In Progress | N13: CA qualified
A14: REC011 | B14: Rohit Verma | C14: Senior Frontend Engineer | D14: Engineering | E14: LinkedIn | F14: 45691 | G14: Hired | H14: Priya Sharma | I14: 45700 | J14: 45710 | K14: 45717 | L14: 26 | M14: Closed | N14: React/Next.js expert
A15: REC012 | B15: Divya Krishnaswamy | C15: Scrum Master | D15: Product | E15: Naukri | F15: 45693 | G15: Withdrawn | H15: Deepa Menon | I15: 45703 | K15: 45708 | L15: 15 | M15: Closed | N15: Accepted counter-offer
A16: REC013 | B16: Sanjay Thakur | C16: ML Engineer | D16: AI/ML | E16: LinkedIn | F16: 45696 | G16: Technical Round | H16: Anil Kumar | I16: 45713 | L16: =IFERROR(K16-F16,"-") -> -45696 | M16: In Progress | N16: PhD - NLP focus
A17: REC014 | B17: Preethi Menon | C17: Business Analyst | D17: Analytics | E17: Naukri | F17: 45698 | G17: Final Round | H17: Rahul Nair | I17: 45716 | L17: =IFERROR(K17-F17,"-") -> -45698 | M17: In Progress | N17: 6 yrs exp
A18: REC015 | B18: Ashwin Kumar | C18: Security Engineer | D18: Infrastructure | E18: Referral (Internal) | F18: 45700 | G18: Hired | H18: Karan Malhotra | I18: 45710 | J18: 45720 | K18: 45731 | L18: 31 | M18: Closed | N18: CISSP certified
A19: REC016 | B19: Nisha Agarwal | C19: Technical Writer | D19: Engineering | E19: LinkedIn | F19: 45703 | G19: Screening | H19: Sunita Patel | L19: =IFERROR(K19-F19,"-") -> -45703 | M19: In Progress | N19: Portfolio review pending
A20: REC017 | B20: Vivek Chandran | C20: Backend Engineer (Python) | D20: Engineering | E20: HackerEarth | F20: 45706 | G20: Rejected | H20: Priya Sharma | I20: 45716 | K20: 45721 | L20: 15 | M20: Closed | N20: Weak system design
A21: REC018 | B21: Rekha Sundaram | C21: Customer Success Manager | D21: Sales | E21: LinkedIn | F21: 45708 | G21: Offer Extended | H21: Deepa Menon | I21: 45721 | J21: 45734 | L21: =IFERROR(K21-F21,"-") -> -45708 | M21: In Progress | N21: SaaS background
A22: REC019 | B22: Manoj Pillai | C22: Data Engineer | D22: Analytics | E22: Naukri | F22: 45710 | G22: Technical Round | H22: Rahul Nair | I22: 45726 | L22: =IFERROR(K22-F22,"-") -> -45710 | M22: In Progress | N22: Spark/Kafka exp
A23: REC020 | B23: Kavitha Rajan | C23: Graphic Designer | D23: Design | E23: Behance | F23: 45713 | G23: HR Interview | H23: Sunita Patel | I23: 45724 | L23: =IFERROR(K23-F23,"-") -> -45713 | M23: In Progress | N23: Strong brand design
A26: Total Applications | C26: Hired | E26: Rejected | G26: In Progress | I26: Avg. Days to Close (closed roles)
B27: =COUNTA(A4:A23) -> 20 | D27: =COUNTIF(G4:G23,"Hired") -> 5 | F27: =COUNTIF(G4:G23,"Rejected") -> 3 | H27: =COUNTIF(M4:M23,"In Progress") -> 11 | J27: =IFERROR(AVERAGEIF(M4:M23,"Closed",L4:L23),"N/A") -> 24.333333

Sheet Onboarding Tracker
A1: EMPLOYEE ONBOARDING TRACKER - FY 2024-25 | TechNova Solutions Pvt. Ltd.
A2: 📋 Source: HR System (HRMS) + Onboarding Portal | Updated: June 2025 | ✅ = Complete ❌ = Pending 🔄 = In Progress
A3: Emp ID | B3: Employee Name | C3: Department | D3: Role | E3: Date of Joining | F3: Buddy Assigned | G3: IT Setup | H3: ID Card & Access | I3: HR Induction | J3: Policy Orientation | K3: Tool Training | L3: 30-Day Check-in | M3: 60-Day Check-in | N3: 90-Day Check-in | O3: Overall Status
A4: EMP101 | B4: Arjun Mehta | C4: Engineering | D4: Senior Backend Engineer | E4: 45689 | F4: Priya Sharma | G4: ✅ | H4: ✅ | I4: ✅ | J4: ✅ | K4: ✅ | L4: ✅ | M4: ✅ | N4: ✅ | O4: Complete
A5: EMP102 | B5: Sneha Rao | C5: Analytics | D5: Data Analyst | E5: 45698 | F5: Rahul Nair | G5: ✅ | H5: ✅ | I5: ✅ | J5: ✅ | K5: ✅ | L5: ✅ | M5: 🔄 | N5: ❌ | O5: In Progress
A6: EMP103 | B6: Ravi Gupta | C6: Quality Assurance | D6: QA Engineer | E6: 45703 | F6: Karan Malhotra | G6: ✅ | H6: ✅ | I6: ✅ | J6: ✅ | K6: ✅ | L6: ✅ | M6: 🔄 | N6: ❌ | O6: In Progress
A7: EMP104 | B7: Rohit Verma | C7: Engineering | D7: Senior Frontend Engineer | E7: 45717 | F7: Priya Sharma | G7: ✅ | H7: ✅ | I7: ✅ | J7: ✅ | K7: 🔄 | L7: ❌ | M7: ❌ | N7: ❌ | O7: In Progress
A8: EMP105 | B8: Ashwin Kumar | C8: Infrastructure | D8: Security Engineer | E8: 45731 | F8: Anil Kumar | G8: ✅ | H8: ✅ | I8: ✅ | J8: ✅ | K8: 🔄 | L8: ❌ | M8: ❌ | N8: ❌ | O8: In Progress
A9: EMP106 | B9: Divya Krishnaswamy | C9: Product | D9: Scrum Master | E9: 45597 | F9: Deepa Menon | G9: ✅ | H9: ✅ | I9: ✅ | J9: ✅ | K9: ✅ | L9: ✅ | M9: ✅ | N9: ✅ | O9: Complete
A10: EMP107 | B10: Preethi Menon | C10: Analytics | D10: Business Analyst | E10: 45611 | F10: Rahul Nair | G10: ✅ | H10: ✅ | I10: ✅ | J10: ✅ | K10: ✅ | L10: ✅ | M10: ✅ | N10: ✅ | O10: Complete
A11: EMP108 | B11: Ananya Das | C11: Design | D11: UX Designer | E11: 45627 | F11: Sunita Patel | G11: ✅ | H11: ✅ | I11: ✅ | J11: ✅ | K11: ✅ | L11: ✅ | M11: ✅ | N11: ✅ | O11: Complete
A12: EMP109 | B12: Manoj Pillai | C12: Analytics | D12: Data Engineer | E12: 45636 | F12: Rahul Nair | G12: ✅ | H12: ✅ | I12: ✅ | J12: ✅ | K12: ✅ | L12: ✅ | M12: ✅ | N12: ❌ | O12: In Progress
A13: EMP110 | B13: Kavitha Rajan | C13: Design | D13: Graphic Designer | E13: 45662 | F13: Sunita Patel | G13: ✅ | H13: ✅ | I13: ✅ | J13: ✅ | K13: ✅ | L13: ✅ | M13: ✅ | N13: ✅ | O13: Complete
A14: EMP111 | B14: Sanjay Thakur | C14: AI/ML | D14: ML Engineer | E14: 45667 | F14: Anil Kumar | G14: ✅ | H14: ✅ | I14: ✅ | J14: ✅ | K14: ✅ | L14: ✅ | M14: ✅ | N14: 🔄 | O14: In Progress
A15: EMP112 | B15: Lakshmi Nair | C15: Finance | D15: Finance Analyst | E15: 45677 | F15: Divya Nambiar | G15: ✅ | H15: ✅ | I15: ✅ | J15: ✅ | K15: ✅ | L15: ✅ | M15: 🔄 | N15: ❌ | O15: In Progress
... A18: EMP115 | B18: Nisha Agarwal | C18: Engineering | D18: Technical Writer | E18: 45748 | F18: Sunita Patel | G18: ❌ | H18: ❌ | I18: ❌ | J18: ❌ | K18: ❌ | L18: ❌ | M18: ❌ | N18: ❌ | O18: Not Started
A21: Total Onboarded | C21: Complete | E21: In Progress | G21: Not Started | I21: Completion Rate
B22: =COUNTA(A4:A18) -> 15 | D22: =COUNTIF(O4:O18,"Complete") -> 7 | F22: =COUNTIF(O4:O18,"In Progress") -> 7 | H22: =COUNTIF(O4:O18,"Not Started") -> 1 | J22: =IFERROR(COUNTIF(O4:O18,"Complete")/COUNTA(O4:O18),0) -> 0.46666667

Sheet Attrition Data
A1: ATTRITION & EXIT DATA - FY 2024-25 | TechNova Solutions Pvt. Ltd.
A2: 📋 Source: Exit Interviews + HRMS Records | Updated: June 2025 | Voluntary = Employee-initiated | Involuntary = Company-initiated
A3: Exit ID | B3: Employee Name | C3: Department | D3: Role | E3: Date of Joining | F3: Date of Exit | G3: Tenure (Months) | H3: Exit Type | I3: Primary Reason | J3: Secondary Reason | K3: Exit Interview Done | L3: Performance Band | M3: Notes
A4: EX001 | B4: Aakash Joshi | C4: Engineering | D4: Backend Engineer | E4: 44713 | F4: 45504 | G4: 26 | H4: Voluntary | I4: Better Compensation | J4: Growth Opportunity | K4: Yes | L4: B | M4: Joined competitor
A5: EX002 | B5: Meena Thomas | C5: Analytics | D5: Data Scientist | E5: 44454 | F5: 45519 | G5: 47 | H5: Voluntary | I5: Relocation | J5: Personal Reason | K5: Yes | L5: A | M5: Moving to Bangalore
A6: EX003 | B6: Siddharth Pillai | C6: Infrastructure | D6: Cloud Engineer | E6: 44936 | F6: 45535 | G6: 20 | H6: Voluntary | I6: Better Compensation | J6: Lack of Growth | K6: Yes | L6: B+ | M6: Startup offer
A7: EX004 | B7: Priya Sharma | C7: Quality Assurance | D7: QA Lead | E7: 43922 | F7: 45550 | G7: 65 | H7: Involuntary | I7: Performance Issues | J7: Attendance | K7: Yes | L7: C | M7: PIP not met
A8: EX005 | B8: Ramesh Nair | C8: Sales | D8: Account Executive | E8: 44990 | F8: 45565 | G8: 19 | H8: Voluntary | I8: Career Change | J8: Work-Life Balance | K8: Yes | L8: B | M8: Moving to non-tech
A9: EX006 | B9: Sunita Pillai | C9: Design | D9: Product Designer | E9: 44866 | F9: 45575 | G9: 23 | H9: Voluntary | I9: Better Compensation | J9: Manager Conflict | K9: No | L9: B+ | M9: Counter-offer lost
A10: EX007 | B10: Arvind Rao | C10: Engineering | D10: Full Stack Developer | E10: 45078 | F10: 45596 | G10: 17 | H10: Voluntary | I10: Higher Studies | J10: Personal Reason | K10: Yes | L10: A- | M10: MS in USA
A11: EX008 | B11: Lakshmi Das | C11: Human Resources | D11: HR Executive | E11: 44423 | F11: 45611 | G11: 39 | H11: Involuntary | I11: Restructuring | J11: Role Redundancy | K11: Yes | L11: B | M11: Dept restructure
A12: EX009 | B12: Kiran Menon | C12: Finance | D12: Senior Finance Analyst | E12: 44562 | F12: 45626 | G12: 35 | H12: Voluntary | I12: Better Compensation | J12: Manager Conflict | K12: Yes | L12: B+ | M12: BFSI sector move
A13: EX010 | B13: Neha Agarwal | C13: Engineering | D13: Frontend Engineer | E13: 45170 | F13: 45641 | G13: 16 | H13: Voluntary | I13: Work-Life Balance | J13: Remote Work Preference | K13: Yes | L13: B | M13: WFH not approved
A14: EX011 | B14: Gautam Shetty | C14: AI/ML | D14: ML Research Engineer | E14: 44743 | F14: 45667 | G14: 30 | H14: Voluntary | I14: Better Compensation | J14: Research Opportunity | K14: Yes | L14: A | M14: FAANG offer
A15: EX012 | B15: Pallavi Raj | C15: Product | D15: Associate PM | E15: 45200 | F15: 45688 | G15: 16 | H15: Voluntary | I15: Better Opportunity | J15: Growth Opportunity | K15: No | L15: B | M15: Startup opportunity
... A21: EX018 | B21: Geetha Varghese | C21: Engineering | D21: QA Engineer | E21: 45017 | F21: 45777 | G21: 25 | H21: Voluntary | I21: Higher Studies | J21: Career Change | K21: Yes | L21: B | M21: MBA program
A24: Total Exits | C24: Voluntary | E24: Involuntary | G24: Avg. Tenure (Months) | I24: Exit Interview Done
B25: =COUNTA(A4:A21) -> 18 | D25: =COUNTIF(H4:H21,"Voluntary") -> 14 | F25: =COUNTIF(H4:H21,"Involuntary") -> 4 | H25: =AVERAGE(G4:G21) -> 29.444444 | J25: =COUNTIF(K4:K21,"Yes") -> 15
