Workbook

Sheet HR Dashboard
A1: 🏢 HR ANALYTICS DASHBOARD | FY 2024-25
A2: Last Refreshed: June 2025 | Data Sources: ATS · HRMS · Exit Records | For Internal HR Use Only
A4: 📌 SECTION A - RECRUITMENT PIPELINE SUMMARY
A5: Total Applications | D5: Positions Filled | E5: Rejections | H5: Open Positions | K5: Avg. Days to Close
A6: ='Recruitment Pipeline'!B27 -> 20 | D6: ='Recruitment Pipeline'!D27 -> 5 | E6: ='Recruitment Pipeline'!F27 -> 3 | H6: ='Recruitment Pipeline'!H27 -> 11 | K6: ='Recruitment Pipeline'!J27 -> 24.333333
A8: # | D8: # | E8: # | H8: # | K8: (days)
A10: Pipeline Stage Breakdown - Candidates by Stage
A11: Stage | B11: Count | C11: % of Total | D11: Notes / Action Required
A12: Screening | B12: 2 | C12: 0.1 | D12: Initial shortlist in progress
A13: Technical Round | B13: 3 | C13: 0.15 | D13: Assignments sent to 3 candidates
A14: HR Interview | B14: 2 | C14: 0.1 | D14: Scheduled for next week
A15: Final Round | B15: 2 | C15: 0.1 | D15: 2 candidates - decision pending
A16: Offer Extended | B16: 2 | C16: 0.1 | D16: Awaiting candidate response
A17: Hired | B17: 6 | C17: 0.3 | D17: Target: 15 hires per quarter
A18: Rejected | B18: 4 | C18: 0.2 | D18: Primarily tech screen rejections
A19: Withdrawn | B19: 1 | C19: 0.05 | D19: Counter-offer cases
A22: 📌 SECTION B - ONBOARDING STATUS SUMMARY
A23: Total Onboarded | D23: Fully Complete | E23: In Progress | H23: Not Started | K23: Completion Rate
A24: ='Onboarding Tracker'!B22 -> 15 | D24: ='Onboarding Tracker'!D22 -> 7 | E24: ='Onboarding Tracker'!F22 -> 7 | H24: ='Onboarding Tracker'!H22 -> 1 | K24: ='Onboarding Tracker'!J22 -> 0.46666667
A26: (count) | D26: (count) | E26: (count) | H26: (count) | K26: (rate)
A28: Onboarding Checklist Completion - % Employees with Task Complete
A29: Onboarding Task | B29: Completed (of 15) | C29: Completion % | D29: Status
A30: IT Setup | B30: 15 | C30: 1 | D30: ✅ On Track
A31: ID Card & Access | B31: 15 | C31: 1 | D31: ✅ On Track
A32: HR Induction | B32: 15 | C32: 1 | D32: ✅ On Track
A33: Policy Orientation | B33: 15 | C33: 1 | D33: ✅ On Track
A34: Tool Training | B34: 14 | C34: 0.93333333 | D34: ✅ On Track
A35: 30-Day Check-in | B35: 14 | C35: 0.93333333 | D35: ✅ On Track
A36: 60-Day Check-in | B36: 10 | C36: 0.66666667 | D36: 🔄 In Progress
A37: 90-Day Check-in | B37: 6 | C37: 0.4 | D37: 🔄 In Progress
A40: 📌 SECTION C - ATTRITION & EXIT SUMMARY
A41: Total Exits (FY) | D41: Voluntary | E41: Involuntary | H41: Avg. Tenure | K41: Exit Int. Done
A42: ='Attrition Data'!B25 -> 18 | D42: ='Attrition Data'!D25 -> 14 | E42: ='Attrition Data'!F25 -> 4 | H42: ='Attrition Data'!H25 -> 29.444444 | K42: ='Attrition Data'!J25 -> 15
A44: (#) | D44: (#) | E44: (#) | H44: (months) | K44: (#)
A46: Attrition by Department & Primary Exit Reason
A47: Department | B47: Exits | C47: % of Total | D47: Top Reason
A48: Engineering | B48: 6 | C48: 0.28571429 | D48: Better Compensation / Growth
A49: Analytics | B49: 3 | C49: 0.14285714 | D49: Relocation / Better Opportunity
A50: Infrastructure | B50: 3 | C50: 0.14285714 | D50: Better Compensation / Restructuring
A51: Sales | B51: 2 | C51: 0.095238095 | D51: Career Change / Targets
...

Sheet Recruitment Pipeline
A1: RECRUITMENT PIPELINE TRACKER - FY 2024-25 | Company Name
A2: 📋 Source: Applicant Tracking System (ATS) + Recruiter Sheets | Updated: June 2025
A3: Candidate ID | B3: Candidate Name | C3: Role / Position | D3: Department | E3: Source | F3: Date Applied | G3: Current Stage | H3: Interviewer / Owner | I3: Interview Date | J3: Offer Date | K3: Date Closed | L3: Days to Close | M3: Status | N3: Notes
A4: REC001 | B4: Arjun Mehta | C4: Senior Backend Engineer | D4: Engineering | E4: LinkedIn | F4: 45662 | G4: Hired | H4: Priya Sharma | I4: 45672 | J4: 45682 | K4: 45689 | L4: 27 | M4: Closed | N4: Joined Feb 1
A5: REC002 | B5: Sneha Rao | C5: Data Analyst | D5: Analytics | E5: Naukri | F5: 45665 | G5: Hired | H5: Rahul Nair | I5: 45677 | J5: 45687 | K5: 45698 | L5: 33 | M5: Closed | N5: Strong SQL skills
A6: REC003 | B6: Vikram Iyer | C6: DevOps Engineer | D6: Infrastructure | E6: Referral (Internal) | F6: 45667 | G6: Rejected | H6: Anil Kumar | I6: 45679 | K6: 45693 | L6: 26 | M6: Closed | N6: Failed system design
A7: REC004 | B7: Pooja Krishnan | C7: Product Manager | D7: Product | E7: LinkedIn | F7: 45672 | G7: Final Round | H7: Deepa Menon | I7: 45698 | L7: =IFERROR(K7-F7,"-") -> -45672 | M7: In Progress | N7: Strong candidate
A8: REC005 | B8: Ravi Gupta | C8: QA Engineer | D8: Quality Assurance | E8: Indeed | F8: 45675 | G8: Hired | H8: Karan Malhotra | I8: 45685 | J8: 45693 | K8: 45703 | L8: 28 | M8: Closed | N8: Automation expertise
A9: REC006 | B9: Ananya Singh | C9: UX Designer | D9: Design | E9: Dribbble | F9: 45677 | G9: Offer Extended | H9: Sunita Patel | I9: 45690 | J9: 45708 | L9: =IFERROR(K9-F9,"-") -> -45677 | M9: In Progress | N9: Portfolio impressive
A10: REC007 | B10: Karthik Suresh | C10: Cloud Architect | D10: Infrastructure | E10: LinkedIn | F10: 45679 | G10: Technical Round | H10: Anil Kumar | I10: 45693 | L10: =IFERROR(K10-F10,"-") -> -45679 | M10: In Progress | N10: AWS certified
A11: REC008 | B11: Meera Pillai | C11: HR Business Partner | D11: Human Resources | E11: Naukri | F11: 45682 | G11: Screening | H11: Divya Nambiar | L11: =IFERROR(K11-F11,"-") -> -45682 | M11: In Progress | N11: Screening scheduled Feb 28
A12: REC009 | B12: Suresh Babu | C12: Mobile Developer (iOS) | D12: Engineering | E12: AngelList | F12: 45685 | G12: Rejected | H12: Priya Sharma | I12: 45696 | K12: 45703 | L12: 18 | M12: Closed | N12: No SwiftUI exp.
A13: REC010 | B13: Lakshmi Nair | C13: Finance Analyst | D13: Finance | E13: Referral (External) | F13: 45689 | G13: HR Interview | H13: Rahul Nair | I13: 45703 | L13: =IFERROR(K13-F13,"-") -> -45689 | M13: In Progress | N13: CA qualified
A14: REC011 | B14: Rohit Verma | C14: Senior Frontend Engineer | D14: Engineering | E14: LinkedIn | F14: 45691 | G14: Hired | H14: Priya Sharma | I14: 45700 | J14: 45710 | K14: 45717 | L14: 26 | M14: Closed | N14: React/Next.js expert
A15: REC012 | B15: Divya Krishnaswamy | C15: Scrum Master | D15: Product | E15: Naukri | F15: 45693 | G15: Withdrawn | H15: Deepa Menon | I15: 45703 | K15: 45708 | L15: 15 | M15: Closed | N15: Accepted counter-offer
A16: REC013 | B16: Sanjay Thakur | C16: ML Engineer | D16: AI/ML | E16: LinkedIn | F16: 45696 | G16: Technical Round | H16: Anil Kumar | I16: 45713 | L16: =IFERROR(K16-F16,"-") -> -45696 | M16: In Progress | N16: PhD - NLP focus
A17: REC014 | B17: Preethi Menon | C17: Business Analyst | D17: Analytics | E17: Naukri | F17: 45698 | G17: Final Round | H17: Rahul Nair | I17: 45716 | L17: =IFERROR(K17-F17,"-") -> -45698 | M17: In Progress | N17: 6 yrs exp
A18: REC015 | B18: Ashwin Kumar | C18: Security Engineer | D18: Infrastructure | E18: Referral (Internal) | F18: 45700 | G18: Hired | H18: Karan Malhotra | I18: 45710 | J18: 45720 | K18: 45731 | L18: 31 | M18: Closed | N18: CISSP certified
A19: REC016 | B19: Nisha Agarwal | C19: Technical Writer | D19: Engineering | E19: LinkedIn | F19: 45703 | G19: Screening | H19: Sunita Patel | L19: =IFERROR(K19-F19,"-") -> -45703 | M19: In Progress | N19: Portfolio review pending
A20: REC017 | B20: Vivek Chandran | C20: Backend Engineer (Python) | D20: Engineering | E20: HackerEarth | F20: 45706 | G20: Rejected | H20: Priya Sharma | I20: 45716 | K20: 45721 | L20: 15 | M20: Closed | N20: Weak system design
A21: REC018 | B21: Rekha Sundaram | C21: Customer Success Manager | D21: Sales | E21: LinkedIn | F21: 45708 | G21: Offer Extended | H21: Deepa Menon | I21: 45721 | J21: 45734 | L21: =IFERROR(K21-F21,"-") -> -45708 | M21: In Progress | N21: SaaS background
A22: REC019 | B22: Manoj Pillai | C22: Data Engineer | D22: Analytics | E22: Naukri | F22: 45710 | G22: Technical Round | H22: Rahul Nair | I22: 45726 | L22: =IFERROR(K22-F22,"-") -> -45710 | M22: In Progress | N22: Spark/Kafka exp
A23: REC020 | B23: Kavitha Rajan | C23: Graphic Designer | D23: Design | E23: Behance | F23: 45713 | G23: HR Interview | H23: Sunita Patel | I23: 45724 | L23: =IFERROR(K23-F23,"-") -> -45713 | M23: In Progress | N23: Strong brand design
A26: Total Applications | C26: Hired | E26: Rejected | G26: In Progress | I26: Avg. Days to Close (closed roles)
B27: =COUNTA(A4:A23) -> 20 | D27: =COUNTIF(G4:G23,"Hired") -> 5 | F27: =COUNTIF(G4:G23,"Rejected") -> 3 | H27: =COUNTIF(M4:M23,"In Progress") -> 11 | J27: =IFERROR(AVERAGEIF(M4:M23,"Closed",L4:L23),"N/A") -> 24.333333

Sheet Onboarding Tracker
A1: EMPLOYEE ONBOARDING TRACKER - FY 2024-25 | Company Name
A2: 📋 Source: HR System (HRMS) + Onboarding Portal | Updated: June 2025 | ✅ = Complete ❌ = Pending 🔄 = In Progress
A3: Emp ID | B3: Employee Name | C3: Department | D3: Role | E3: Date of Joining | F3: Buddy Assigned | G3: IT Setup | H3: ID Card & Access | I3: HR Induction | J3: Policy Orientation | K3: Tool Training | L3: 30-Day Check-in | M3: 60-Day Check-in | N3: 90-Day Check-in | O3: Overall Status
A4: EMP101 | B4: Arjun Mehta | C4: Engineering | D4: Senior Backend Engineer | E4: 45689 | F4: Priya Sharma | G4: ✅ | H4: ✅ | I4: ✅ | J4: ✅ | K4: ✅ | L4: ✅ | M4: ✅ | N4: ✅ | O4: Complete
A5: EMP102 | B5: Sneha Rao | C5: Analytics | D5: Data Analyst | E5: 45698 | F5: Rahul Nair | G5: ✅ | H5: ✅ | I5: ✅ | J5: ✅ | K5: ✅ | L5: ✅ | M5: 🔄 | N5: ❌ | O5: In Progress
A6: EMP103 | B6: Ravi Gupta | C6: Quality Assurance | D6: QA Engineer | E6: 45703 | F6: Karan Malhotra | G6: ✅ | H6: ✅ | I6: ✅ | J6: ✅ | K6: ✅ | L6: ✅ | M6: 🔄 | N6: ❌ | O6: In Progress
A7: EMP104 | B7: Rohit Verma | C7: Engineering | D7: Senior Frontend Engineer | E7: 45717 | F7: Priya Sharma | G7: ✅ | H7: ✅ | I7: ✅ | J7: ✅ | K7: 🔄 | L7: ❌ | M7: ❌ | N7: ❌ | O7: In Progress
A8: EMP105 | B8: Ashwin Kumar | C8: Infrastructure | D8: Security Engineer | E8: 45731 | F8: Anil Kumar | G8: ✅ | H8: ✅ | I8: ✅ | J8: ✅ | K8: 🔄 | L8: ❌ | M8: ❌ | N8: ❌ | O8: In Progress
A9: EMP106 | B9: Divya Krishnaswamy | C9: Product | D9: Scrum Master | E9: 45597 | F9: Deepa Menon | G9: ✅ | H9: ✅ | I9: ✅ | J9: ✅ | K9: ✅ | L9: ✅ | M9: ✅ | N9: ✅ | O9: Complete
A10: EMP107 | B10: Preethi Menon | C10: Analytics | D10: Business Analyst | E10: 45611 | F10: Rahul Nair | G10: ✅ | H10: ✅ | I10: ✅ | J10: ✅ | K10: ✅ | L10: ✅ | M10: ✅ | N10: ✅ | O10: Complete
A11: EMP108 | B11: Ananya Das | C11: Design | D11: UX Designer | E11: 45627 | F11: Sunita Patel | G11: ✅ | H11: ✅ | I11: ✅ | J11: ✅ | K11: ✅ | L11: ✅ | M11: ✅ | N11: ✅ | O11: Complete
A12: EMP109 | B12: Manoj Pillai | C12: Analytics | D12: Data Engineer | E12: 45636 | F12: Rahul Nair | G12: ✅ | H12: ✅ | I12: ✅ | J12: ✅ | K12: ✅ | L12: ✅ | M12: ✅ | N12: ❌ | O12: In Progress
A13: EMP110 | B13: Kavitha Rajan | C13: Design | D13: Graphic Designer | E13: 45662 | F13: Sunita Patel | G13: ✅ | H13: ✅ | I13: ✅ | J13: ✅ | K13: ✅ | L13: ✅ | M13: ✅ | N13: ✅ | O13: Complete
A14: EMP111 | B14: Sanjay Thakur | C14: AI/ML | D14: ML Engineer | E14: 45667 | F14: Anil Kumar | G14: ✅ | H14: ✅ | I14: ✅ | J14: ✅ | K14: ✅ | L14: ✅ | M14: ✅ | N14: 🔄 | O14: In Progress
A15: EMP112 | B15: Lakshmi Nair | C15: Finance | D15: Finance Analyst | E15: 45677 | F15: Divya Nambiar | G15: ✅ | H15: ✅ | I15: ✅ | J15: ✅ | K15: ✅ | L15: ✅ | M15: 🔄 | N15: ❌ | O15: In Progress
... A18: EMP115 | B18: Nisha Agarwal | C18: Engineering | D18: Technical Writer | E18: 45748 | F18: Sunita Patel | G18: ❌ | H18: ❌ | I18: ❌ | J18: ❌ | K18: ❌ | L18: ❌ | M18: ❌ | N18: ❌ | O18: Not Started
A21: Total Onboarded | C21: Complete | E21: In Progress | G21: Not Started | I21: Completion Rate
B22: =COUNTA(A4:A18) -> 15 | D22: =COUNTIF(O4:O18,"Complete") -> 7 | F22: =COUNTIF(O4:O18,"In Progress") -> 7 | H22: =COUNTIF(O4:O18,"Not Started") -> 1 | J22: =IFERROR(COUNTIF(O4:O18,"Complete")/COUNTA(O4:O18),0) -> 0.46666667

Sheet Attrition Data
A1: ATTRITION & EXIT DATA - FY 2024-25 | Company Name
A2: 📋 Source: Exit Interviews + HRMS Records | Updated: June 2025 | Voluntary = Employee-initiated | Involuntary = Company-initiated
A3: Exit ID | B3: Employee Name | C3: Department | D3: Role | E3: Date of Joining | F3: Date of Exit | G3: Tenure (Months) | H3: Exit Type | I3: Primary Reason | J3: Secondary Reason | K3: Exit Interview Done | L3: Performance Band | M3: Notes
A4: EX001 | B4: Aakash Joshi | C4: Engineering | D4: Backend Engineer | E4: 44713 | F4: 45504 | G4: 26 | H4: Voluntary | I4: Better Compensation | J4: Growth Opportunity | K4: Yes | L4: B | M4: Joined competitor
A5: EX002 | B5: Meena Thomas | C5: Analytics | D5: Data Scientist | E5: 44454 | F5: 45519 | G5: 47 | H5: Voluntary | I5: Relocation | J5: Personal Reason | K5: Yes | L5: A | M5: Moving to Bangalore
A6: EX003 | B6: Siddharth Pillai | C6: Infrastructure | D6: Cloud Engineer | E6: 44936 | F6: 45535 | G6: 20 | H6: Voluntary | I6: Better Compensation | J6: Lack of Growth | K6: Yes | L6: B+ | M6: Startup offer
A7: EX004 | B7: Priya Sharma | C7: Quality Assurance | D7: QA Lead | E7: 43922 | F7: 45550 | G7: 65 | H7: Involuntary | I7: Performance Issues | J7: Attendance | K7: Yes | L7: C | M7: PIP not met
A8: EX005 | B8: Ramesh Nair | C8: Sales | D8: Account Executive | E8: 44990 | F8: 45565 | G8: 19 | H8: Voluntary | I8: Career Change | J8: Work-Life Balance | K8: Yes | L8: B | M8: Moving to non-tech
A9: EX006 | B9: Sunita Pillai | C9: Design | D9: Product Designer | E9: 44866 | F9: 45575 | G9: 23 | H9: Voluntary | I9: Better Compensation | J9: Manager Conflict | K9: No | L9: B+ | M9: Counter-offer lost
A10: EX007 | B10: Arvind Rao | C10: Engineering | D10: Full Stack Developer | E10: 45078 | F10: 45596 | G10: 17 | H10: Voluntary | I10: Higher Studies | J10: Personal Reason | K10: Yes | L10: A- | M10: MS in USA
A11: EX008 | B11: Lakshmi Das | C11: Human Resources | D11: HR Executive | E11: 44423 | F11: 45611 | G11: 39 | H11: Involuntary | I11: Restructuring | J11: Role Redundancy | K11: Yes | L11: B | M11: Dept restructure
A12: EX009 | B12: Kiran Menon | C12: Finance | D12: Senior Finance Analyst | E12: 44562 | F12: 45626 | G12: 35 | H12: Voluntary | I12: Better Compensation | J12: Manager Conflict | K12: Yes | L12: B+ | M12: BFSI sector move
A13: EX010 | B13: Neha Agarwal | C13: Engineering | D13: Frontend Engineer | E13: 45170 | F13: 45641 | G13: 16 | H13: Voluntary | I13: Work-Life Balance | J13: Remote Work Preference | K13: Yes | L13: B | M13: WFH not approved
A14: EX011 | B14: Gautam Shetty | C14: AI/ML | D14: ML Research Engineer | E14: 44743 | F14: 45667 | G14: 30 | H14: Voluntary | I14: Better Compensation | J14: Research Opportunity | K14: Yes | L14: A | M14: FAANG offer
A15: EX012 | B15: Pallavi Raj | C15: Product | D15: Associate PM | E15: 45200 | F15: 45688 | G15: 16 | H15: Voluntary | I15: Better Opportunity | J15: Growth Opportunity | K15: No | L15: B | M15: Startup opportunity
... A21: EX018 | B21: Geetha Varghese | C21: Engineering | D21: QA Engineer | E21: 45017 | F21: 45777 | G21: 25 | H21: Voluntary | I21: Higher Studies | J21: Career Change | K21: Yes | L21: B | M21: MBA program
A24: Total Exits | C24: Voluntary | E24: Involuntary | G24: Avg. Tenure (Months) | I24: Exit Interview Done
B25: =COUNTA(A4:A21) -> 18 | D25: =COUNTIF(H4:H21,"Voluntary") -> 14 | F25: =COUNTIF(H4:H21,"Involuntary") -> 4 | H25: =AVERAGE(G4:G21) -> 29.444444 | J25: =COUNTIF(K4:K21,"Yes") -> 15

Sheet Monthly Trends
A1: 📅 MONTHLY HR METRICS TREND TRACKER | FY 2024-25 | Company Name
A2: 📋 Update monthly - tracks Hiring, Attrition, and Onboarding KPIs over time for trend analysis
A3: 📌 SECTION A - MONTHLY RECRUITMENT METRICS
A4: Metric | B4: Apr-24 | C4: May-24 | D4: Jun-24 | E4: Jul-24 | F4: Aug-24 | G4: Sep-24 | H4: Oct-24 | I4: Nov-24 | J4: Dec-24 | K4: Jan-25 | L4: Feb-25 | M4: Mar-25 | N4: TOTAL / AVG
A5: Applications Received | B5: 8 | C5: 10 | D5: 7 | E5: 12 | F5: 9 | G5: 11 | H5: 14 | I5: 13 | J5: 8 | K5: 20 | L5: 15 | M5: 10 | N5: =SUM(B5:M5) -> 137
A6: Offers Extended | B6: 3 | C6: 4 | D6: 2 | E6: 5 | F6: 3 | G6: 4 | H6: 5 | I6: 4 | J6: 3 | K6: 6 | L6: 4 | M6: 3 | N6: =SUM(B6:M6) -> 46
A7: Hires (Joined) | B7: 2 | C7: 3 | D7: 2 | E7: 4 | F7: 2 | G7: 3 | H7: 4 | I7: 3 | J7: 2 | K7: 5 | L7: 3 | M7: 2 | N7: =SUM(B7:M7) -> 35
A8: Rejections | B8: 4 | C8: 5 | D8: 3 | E8: 6 | F8: 4 | G8: 5 | H8: 7 | I8: 6 | J8: 4 | K8: 8 | L8: 5 | M8: 4 | N8: =SUM(B8:M8) -> 61
A9: Avg. Days to Close | B9: 28 | C9: 30 | D9: 25 | E9: 32 | F9: 27 | G9: 29 | H9: 31 | I9: 28 | J9: 26 | K9: 24 | L9: 27 | M9: 30 | N9: =AVERAGE(B9:M9) -> 28.083333
A10: Offer Acceptance Rate % | B10: 67 | C10: 75 | D10: 100 | E10: 80 | F10: 67 | G10: 75 | H10: 80 | I10: 75 | J10: 67 | K10: 83 | L10: 75 | M10: 67 | N10: =AVERAGE(B10:M10) -> 75.916667
A12: 📌 SECTION B - MONTHLY ATTRITION METRICS
A13: Metric | B13: Apr-24 | C13: May-24 | D13: Jun-24 | E13: Jul-24 | F13: Aug-24 | G13: Sep-24 | H13: Oct-24 | I13: Nov-24 | J13: Dec-24 | K13: Jan-25 | L13: Feb-25 | M13: Mar-25 | N13: TOTAL / AVG
A14: Total Exits | B14: 1 | C14: 2 | D14: 1 | E14: 2 | F14: 3 | G14: 2 | H14: 2 | I14: 2 | J14: 1 | K14: 1 | L14: 2 | M14: 1 | N14: =SUM(B14:M14) -> 20
A15: Voluntary Exits | B15: 1 | C15: 1 | D15: 1 | E15: 2 | F15: 2 | G15: 2 | H15: 2 | I15: 2 | J15: 1 | K15: 1 | L15: 2 | M15: 1 | N15: =SUM(B15:M15) -> 18
A16: Involuntary Exits | B16: 0 | C16: 1 | D16: 0 | E16: 0 | F16: 1 | G16: 0 | H16: 0 | I16: 0 | J16: 0 | K16: 0 | L16: 0 | M16: 0 | N16: =SUM(B16:M16) -> 2
A17: Attrition Rate % | B17: 1.2 | C17: 2.4 | D17: 1.2 | E17: 2.4 | F17: 3.6 | G17: 2.4 | H17: 2.4 | I17: 2.4 | J17: 1.2 | K17: 1.2 | L17: 2.4 | M17: 1.2 | N17: =AVERAGE(B17:M17) -> 2
A18: Avg. Tenure of Exits (Mo) | B18: 30 | C18: 22 | D18: 35 | E18: 26 | F18: 28 | G18: 40 | H18: 23 | I18: 39 | J18: 35 | K18: 26 | L18: 14 | M18: 33 | N18: =AVERAGE(B18:M18) -> 29.25
A20: 📌 SECTION C - MONTHLY ONBOARDING METRICS
A21: Metric | B21: Apr-24 | C21: May-24 | D21: Jun-24 | E21: Jul-24 | F21: Aug-24 | G21: Sep-24 | H21: Oct-24 | I21: Nov-24 | J21: Dec-24 | K21: Jan-25 | L21: Feb-25 | M21: Mar-25 | N21: TOTAL / AVG
A22: New Joiners | B22: 2 | C22: 3 | D22: 2 | E22: 4 | F22: 2 | G22: 3 | H22: 4 | I22: 3 | J22: 2 | K22: 5 | L22: 3 | M22: 2 | N22: =SUM(B22:M22) -> 35
A23: Onboarding Complete | B23: 2 | C23: 3 | D23: 2 | E23: 3 | F23: 2 | G23: 3 | H23: 3 | I23: 3 | J23: 2 | K23: 4 | L23: 2 | M23: 1 | N23: =SUM(B23:M23) -> 30
A24: Onboarding In Progress | B24: 0 | C24: 0 | D24: 0 | E24: 1 | F24: 0 | G24: 0 | H24: 1 | I24: 0 | J24: 0 | K24: 1 | L24: 1 | M24: 1 | N24: =SUM(B24:M24) -> 5
A25: Completion Rate % | B25: 100 | C25: 100 | D25: 100 | E25: 75 | F25: 100 | G25: 100 | H25: 75 | I25: 100 | J25: 100 | K25: 80 | L25: 67 | M25: 50 | N25: =AVERAGE(B25:M25) -> 87.25

Sheet Headcount & Diversity
A1: 👥 HEADCOUNT & DIVERSITY TRACKER | FY 2024-25 | Company Name
A2: 📋 Source: HRMS Employee Master | Updated: June 2025 | Update monthly - tracks workforce composition
A3: 📌 SECTION A - ACTIVE HEADCOUNT BY DEPARTMENT
A4: Department | B4: Total HC | C4: Male | D4: Female | E4: Non-Binary / Prefer not to say | F4: % Women | G4: Avg. Tenure (Mo) | H4: Avg. Age | I4: Open Positions | J4: Notes
A5: Engineering | B5: 28 | C5: 20 | D5: 7 | E5: 1 | F5: =D5/B5 -> 0.25 | G5: 24 | H5: 29 | I5: 4 | J5: Largest dept; 4 open roles
A6: Analytics | B6: 10 | C6: 6 | D6: 4 | E6: 0 | F6: =D6/B6 -> 0.4 | G6: 22 | H6: 31 | I6: 1 | J6: BI + Data Science teams
A7: Infrastructure | B7: 8 | C7: 6 | D7: 2 | E7: 0 | F7: =D7/B7 -> 0.25 | G7: 30 | H7: 33 | I7: 2 | J7: Cloud & Network
A8: Product | B8: 6 | C8: 3 | D8: 3 | E8: 0 | F8: =D8/B8 -> 0.5 | G8: 28 | H8: 30 | I8: 1 | J8: PM + Scrum
A9: Design | B9: 5 | C9: 2 | D9: 3 | E9: 0 | F9: =D9/B9 -> 0.6 | G9: 20 | H9: 27 | I9: 0 | J9: UX + Graphic
A10: AI/ML | B10: 4 | C10: 3 | D10: 1 | E10: 0 | F10: =D10/B10 -> 0.25 | G10: 18 | H10: 28 | I10: 1 | J10: Research & Applied ML
A11: Sales | B11: 7 | C11: 4 | D11: 3 | E11: 0 | F11: =D11/B11 -> 0.42857143 | G11: 26 | H11: 32 | I11: 1 | J11: SMB + Enterprise
A12: Human Resources | B12: 4 | C12: 1 | D12: 3 | E12: 0 | F12: =D12/B12 -> 0.75 | G12: 32 | H12: 34 | I12: 0 | J12: HRBP + Ops
A13: Finance | B13: 4 | C13: 2 | D13: 2 | E13: 0 | F13: =D13/B13 -> 0.5 | G13: 36 | H13: 35 | I13: 0 | J13: FP&A + Accounts
A14: Marketing | B14: 3 | C14: 1 | D14: 2 | E14: 0 | F14: =D14/B14 -> 0.66666667 | G14: 18 | H14: 26 | I14: 1 | J14: Content + Growth
A15: TOTAL | B15: =SUM(B5:B14) -> 79 | C15: =SUM(C5:C14) -> 48 | D15: =SUM(D5:D14) -> 30 | E15: =SUM(E5:E14) -> 1 | F15: =IFERROR(D15/B15,0) -> 0.37974684 | G15: =IFERROR(AVERAGE(G5:G14),0) -> 25.4 | H15: =IFERROR(AVERAGE(H5:H14),0) -> 30.5 | I15: =SUM(I5:I14) -> 11
A17: 📌 SECTION B - DIVERSITY SUMMARY METRICS
A18: Metric | B18: Value | C18: Target | D18: Status | E18: Notes
A19: Overall % Women in Workforce | B19: =IFERROR(SUM(D5:D14)/SUM(B5:B14),0) -> 0.37974684 | C19: 35% | D19: =IF(B19>=0.35,"✅ On Target","⚠️ Below Target") -> ✅ On Target
A20: Women in Tech Roles (Eng+AI/ML) | B20: =IFERROR((D5+D10)/(B5+B10),0) -> 0.25 | C20: 30% | D20: =IF(B20>=0.3,"✅ On Target","⚠️ Below Target") -> ⚠️ Below Target
A21: Women in Leadership (Mgr+) | B21: 30% | C21: 40% | D21: ⚠️ Below Target
A22: New Hires - % Women (FY25) | B22: =IFERROR(COUNTIF('Recruitment Pipeline'!D4:D23,"*"),0) -> 20 | C22: 40% | D22: Manual check needed
A23: Attrition - % Women Exited | B23: =IFERROR(COUNTIF('Attrition Data'!B4:B23,"*"),0) -> 18 | C23: < Company avg | D23: Manual check
A25: 📌 SECTION C - HEADCOUNT MOVEMENT (FY 2024-25)
A26: Month | B26: Opening HC | C26: Joiners | D26: Exits | E26: Closing HC | F26: Net Change | G26: Notes
A27: Apr-24 | B27: 72 | C27: 2 | D27: 1 | E27: 73 | F27: 1
A28: May-24 | B28: 73 | C28: 3 | D28: 2 | E28: 74 | F28: 1
A29: Jun-24 | B29: 74 | C29: 2 | D29: 1 | E29: 75 | F29: 1
A30: Jul-24 | B30: 75 | C30: 4 | D30: 2 | E30: 77 | F30: 2
A31: Aug-24 | B31: 77 | C31: 2 | D31: 3 | E31: 76 | F31: -1 | G31: High attrition month
A32: Sep-24 | B32: 76 | C32: 3 | D32: 2 | E32: 77 | F32: 1
A33: Oct-24 | B33: 77 | C33: 4 | D33: 2 | E33: 79 | F33: 2
A34: Nov-24 | B34: 79 | C34: 3 | D34: 2 | E34: 80 | F34: 1
A35: Dec-24 | B35: 80 | C35: 2 | D35: 1 | E35: 81 | F35: 1
A36: Jan-25 | B36: 81 | C36: 5 | D36: 1 | E36: 85 | F36: 4 | G36: Hiring push
A37: Feb-25 | B37: 85 | C37: 3 | D37: 2 | E37: 86 | F37: 1
A38: Mar-25 | B38: 86 | C38: 2 | D38: 1 | E38: 87 | F38: 1

Sheet L&D Training Tracker
A1: 🎓 LEARNING & DEVELOPMENT (L&D) TRACKER | FY 2024-25 | Company Name
A2: 📋 Source: LMS + Manager Reports | Updated: June 2025 | Tracks training completion, certifications, and skill coverage
A3: 📌 SECTION A - EMPLOYEE TRAINING LOG
A4: Emp ID | B4: Employee Name | C4: Department | D4: Training Program | E4: Category | F4: Mode | G4: Start Date | H4: Completion Date | I4: Status | J4: Score / Grade | K4: Certification Earned | L4: Valid Until | M4: Cost (INR) | N4: Notes
A5: EMP101 | B5: Arjun Mehta | C5: Engineering | D5: AWS Solutions Architect | E5: Cloud | F5: Online | G5: 45667 | H5: 45703 | I5: Complete | J5: 87/100 | K5: AWS SAA-C03 | L5: 46433 | M5: 15000 | N5: Passed first attempt
A6: EMP102 | B6: Sneha Rao | C6: Analytics | D6: Advanced SQL & dbt | E6: Data Engineering | F6: Online | G6: 45672 | H6: 45708 | I6: Complete | J6: 92/100 | K6: None | M6: 8000 | N6: Internal LMS
A7: EMP103 | B7: Ravi Gupta | C7: Quality Assurance | D7: Selenium + Cypress Automation | E7: QA Automation | F7: Online | G7: 45689 | H7: 45726 | I7: Complete | J7: Pass | K7: ISTQB Automation | L7: 46822 | M7: 12000
A8: EMP104 | B8: Rohit Verma | C8: Engineering | D8: Next.js 14 & React Advanced | E8: Frontend | F8: Online | G8: 45693 | I8: In Progress | J8: - | K8: None | M8: 5000 | N8: Self-paced Udemy
A9: EMP105 | B9: Ashwin Kumar | C9: Infrastructure | D9: CISSP Refresher | E9: Security | F9: Classroom | G9: 45717 | H9: 45736 | I9: Complete | J9: Pass | K9: CISSP CPE | L9: 46101 | M9: 25000 | N9: Annual renewal
A10: EMP106 | B10: Divya Krishnaswamy | C10: Product | D10: Certified Scrum Master (CSM) | E10: Agile | F10: Classroom | G10: 45631 | H10: 45633 | I10: Complete | J10: Pass | K10: CSM | L10: 46363 | M10: 18000 | N10: Scrumalliance
A11: EMP107 | B11: Preethi Menon | C11: Analytics | D11: Tableau Desktop Specialist | E11: BI & Visualization | F11: Online | G11: 45677 | H11: 45716 | I11: Complete | J11: Pass | K11: Tableau DS | L11: 46446 | M11: 10000
A12: EMP108 | B12: Ananya Das | C12: Design | D12: Figma Advanced & Design Systems | E12: Design | F12: Online | G12: 45698 | I12: In Progress | J12: - | K12: None | M12: 4000
A13: EMP109 | B13: Manoj Pillai | C13: Analytics | D13: Apache Spark & Kafka | E13: Data Engineering | F13: Online | G13: 45662 | H13: 45698 | I13: Complete | J13: 88/100 | K13: None | M13: 9000
A14: EMP110 | B14: Kavitha Rajan | C14: Design | D14: Adobe Creative Suite Advanced | E14: Design | F14: Online | G14: 45597 | H14: 45641 | I14: Complete | J14: Pass | K14: Adobe CC | L14: 46006 | M14: 7000
A15: EMP111 | B15: Sanjay Thakur | C15: AI/ML | D15: Deep Learning Specialization | E15: AI/ML | F15: Online | G15: 45658 | H15: 45747 | I15: Complete | J15: 95/100 | K15: Coursera DL | L15: 46477 | M15: 6000 | N15: DeepLearning.AI
A16: EMP112 | B16: Lakshmi Nair | C16: Finance | D16: Financial Modeling & Valuation | E16: Finance | F16: Online | G16: 45689 | I16: In Progress | J16: - | K16: None | M16: 8000
A17: EMP113 | B17: Vivek Chandran | C17: Engineering | D17: Docker & Kubernetes | E17: DevOps | F17: Online | G17: 45672 | H17: 45708 | I17: Complete | J17: Pass | K17: CKA | L17: 46438 | M17: 12000
A18: EMP114 | B18: Rekha Sundaram | C18: Sales | D18: Salesforce Admin Cert | E18: CRM | F18: Online | G18: 45689 | H18: 45731 | I18: Complete | J18: Pass | K18: Salesforce Admin | L18: 46096 | M18: 10000
A19: EMP115 | B19: Nisha Agarwal | C19: Engineering | D19: Technical Writing (DITA) | E19: Writing | F19: Online | G19: 45748 | I19: Not Started | J19: - | K19: None | M19: 5000 | N19: Planned
A20: EMP101 | B20: Arjun Mehta | C20: Engineering | D20: Leadership Essentials | E20: Leadership | F20: Classroom | G20: 45726 | H20: 45728 | I20: Complete | J20: Pass | K20: None | M20: 8000 | N20: In-house program
A22: 📌 SECTION B - L&D SUMMARY METRICS
A23: Metric | B23: Value | C23: Target | D23: Status | E23: Notes
A24: Total Training Sessions (FY25) | B24: =COUNTA(A5:A20) -> 16 | C24: - | D24: -
A25: Employees Trained | B25: =SUMPRODUCT(1/COUNTIF(A5:A20,A5:A20)) -> 15 | C25: 100% | D25: -
A26: Completion Rate | B26: =COUNTIF(I5:I20,"Complete")/COUNTA(I5:I20) -> 0.75 | C26: 85% | D26: =IF(C26>=0.85,"✅ On Target","⚠️ Below") -> ✅ On Target
A27: Certifications Earned | B27: =COUNTA(K5:K20)-COUNTIF(K5:K20,"None") -> 9 | C27: - | D27: -
A28: Total L&D Spend (INR) | B28: =SUM(M5:M20) -> 162000 | C28: - | D28: -
A29: Avg. Cost per Training | B29: =IFERROR(SUM(M5:M20)/COUNTA(A5:A20),0) -> 10125 | C29: - | D29: -

Sheet Leave & Absence
A1: 🗓️ LEAVE & ABSENCE TRACKER | FY 2024-25 | Company Name
A2: 📋 Source: HRMS Leave Module | Updated: June 2025 | Entitlements per company policy: PL=18, SL=12, CL=6 days/year
A3: 📌 SECTION A - EMPLOYEE LEAVE BALANCE & UTILIZATION (FY 2024-25)
A4: Emp ID | B4: Employee Name | C4: Department | D4: PL Entitlement | E4: PL Taken | F4: PL Balance | G4: SL Entitlement | H4: SL Taken | I4: SL Balance | J4: CL Entitlement | K4: CL Taken | L4: CL Balance | M4: Total Days Absent | N4: Absenteeism % | O4: Notes
A5: EMP101 | B5: Arjun Mehta | C5: Engineering | D5: 18 | E5: 8 | F5: =D5-E5 -> 10 | G5: 12 | H5: 2 | I5: =G5-H5 -> 10 | J5: 6 | K5: 1 | L5: =J5-K5 -> 5 | M5: =E5+H5+K5 -> 11 | N5: =(E5+H5+K5)/250 -> 0.044
A6: EMP102 | B6: Sneha Rao | C6: Analytics | D6: 18 | E6: 12 | F6: =D6-E6 -> 6 | G6: 12 | H6: 5 | I6: =G6-H6 -> 7 | J6: 6 | K6: 2 | L6: =J6-K6 -> 4 | M6: =E6+H6+K6 -> 19 | N6: =(E6+H6+K6)/250 -> 0.076
A7: EMP103 | B7: Ravi Gupta | C7: Quality Assurance | D7: 18 | E7: 5 | F7: =D7-E7 -> 13 | G7: 12 | H7: 1 | I7: =G7-H7 -> 11 | J7: 6 | K7: 0 | L7: =J7-K7 -> 6 | M7: =E7+H7+K7 -> 6 | N7: =(E7+H7+K7)/250 -> 0.024
A8: EMP104 | B8: Rohit Verma | C8: Engineering | D8: 18 | E8: 3 | F8: =D8-E8 -> 15 | G8: 12 | H8: 0 | I8: =G8-H8 -> 12 | J8: 6 | K8: 1 | L8: =J8-K8 -> 5 | M8: =E8+H8+K8 -> 4 | N8: =(E8+H8+K8)/250 -> 0.016
A9: EMP105 | B9: Ashwin Kumar | C9: Infrastructure | D9: 18 | E9: 10 | F9: =D9-E9 -> 8 | G9: 12 | H9: 3 | I9: =G9-H9 -> 9 | J9: 6 | K9: 2 | L9: =J9-K9 -> 4 | M9: =E9+H9+K9 -> 15 | N9: =(E9+H9+K9)/250 -> 0.06
A10: EMP106 | B10: Divya Krishnaswamy | C10: Product | D10: 18 | E10: 15 | F10: =D10-E10 -> 3 | G10: 12 | H10: 4 | I10: =G10-H10 -> 8 | J10: 6 | K10: 3 | L10: =J10-K10 -> 3 | M10: =E10+H10+K10 -> 22 | N10: =(E10+H10+K10)/250 -> 0.088 | O10: High absenteeism - review
A11: EMP107 | B11: Preethi Menon | C11: Analytics | D11: 18 | E11: 7 | F11: =D11-E11 -> 11 | G11: 12 | H11: 2 | I11: =G11-H11 -> 10 | J11: 6 | K11: 1 | L11: =J11-K11 -> 5 | M11: =E11+H11+K11 -> 10 | N11: =(E11+H11+K11)/250 -> 0.04
A12: EMP108 | B12: Ananya Das | C12: Design | D12: 18 | E12: 9 | F12: =D12-E12 -> 9 | G12: 12 | H12: 6 | I12: =G12-H12 -> 6 | J12: 6 | K12: 2 | L12: =J12-K12 -> 4 | M12: =E12+H12+K12 -> 17 | N12: =(E12+H12+K12)/250 -> 0.068
A13: EMP109 | B13: Manoj Pillai | C13: Analytics | D13: 18 | E13: 4 | F13: =D13-E13 -> 14 | G13: 12 | H13: 1 | I13: =G13-H13 -> 11 | J13: 6 | K13: 0 | L13: =J13-K13 -> 6 | M13: =E13+H13+K13 -> 5 | N13: =(E13+H13+K13)/250 -> 0.02
A14: EMP110 | B14: Kavitha Rajan | C14: Design | D14: 18 | E14: 11 | F14: =D14-E14 -> 7 | G14: 12 | H14: 3 | I14: =G14-H14 -> 9 | J14: 6 | K14: 1 | L14: =J14-K14 -> 5 | M14: =E14+H14+K14 -> 15 | N14: =(E14+H14+K14)/250 -> 0.06
A15: EMP111 | B15: Sanjay Thakur | C15: AI/ML | D15: 18 | E15: 6 | F15: =D15-E15 -> 12 | G15: 12 | H15: 2 | I15: =G15-H15 -> 10 | J15: 6 | K15: 0 | L15: =J15-K15 -> 6 | M15: =E15+H15+K15 -> 8 | N15: =(E15+H15+K15)/250 -> 0.032
A16: EMP112 | B16: Lakshmi Nair | C16: Finance | D16: 18 | E16: 8 | F16: =D16-E16 -> 10 | G16: 12 | H16: 4 | I16: =G16-H16 -> 8 | J16: 6 | K16: 2 | L16: =J16-K16 -> 4 | M16: =E16+H16+K16 -> 14 | N16: =(E16+H16+K16)/250 -> 0.056
A17: EMP113 | B17: Vivek Chandran | C17: Engineering | D17: 18 | E17: 14 | F17: =D17-E17 -> 4 | G17: 12 | H17: 7 | I17: =G17-H17 -> 5 | J17: 6 | K17: 3 | L17: =J17-K17 -> 3 | M17: =E17+H17+K17 -> 24 | N17: =(E17+H17+K17)/250 -> 0.096 | O17: High absenteeism - review
A18: EMP114 | B18: Rekha Sundaram | C18: Sales | D18: 18 | E18: 10 | F18: =D18-E18 -> 8 | G18: 12 | H18: 5 | I18: =G18-H18 -> 7 | J18: 6 | K18: 2 | L18: =J18-K18 -> 4 | M18: =E18+H18+K18 -> 17 | N18: =(E18+H18+K18)/250 -> 0.068
A19: EMP115 | B19: Nisha Agarwal | C19: Engineering | D19: 18 | E19: 0 | F19: =D19-E19 -> 18 | G19: 12 | H19: 0 | I19: =G19-H19 -> 12 | J19: 6 | K19: 0 | L19: =J19-K19 -> 6 | M19: =E19+H19+K19 -> 0 | N19: =(E19+H19+K19)/250 -> 0
A20: TOTALS / AVG | D20: =AVERAGE(D5:D19) -> 18 | E20: =SUM(F5:F19) -> 148 | G20: =AVERAGE(H5:H19) -> 3 | H20: =SUM(I5:I19) -> 135 | J20: =AVERAGE(K5:K19) -> 1.3333333 | K20: =SUM(L5:L19) -> 70 | M20: =SUM(M5:M19) -> 187 | N20: =AVERAGE(N5:N19) -> 0.049866667
A22: 📌 SECTION B - LEAVE BY TYPE SUMMARY
A23: Leave Type | B23: Total Entitlement | C23: Total Taken | D23: Total Balance | E23: Utilization % | F23: Policy Limit
A24: Planned Leave (PL) | B24: =AVERAGE(D5:D19)*15 -> 270 | C24: =SUM(F5:F19) -> 148 | D24: =B24-C24 -> 122 | E24: =IFERROR(C24/B24,0) -> 0.54814815 | F24: 18 days/year
A25: Sick Leave (SL) | B25: =AVERAGE(H5:H19)*15 -> 45 | C25: =SUM(I5:I19) -> 135 | D25: =B25-C25 -> -90 | E25: =IFERROR(C25/B25,0) -> 3 | F25: 12 days/year
A26: Casual Leave (CL) | B26: =AVERAGE(K5:K19)*15 -> 20 | C26: =SUM(L5:L19) -> 70 | D26: =B26-C26 -> -50 | E26: =IFERROR(C26/B26,0) -> 3.5 | F26: 6 days/year

Sheet Offer Acceptance Rate
A1: 📝 OFFER ACCEPTANCE RATE TRACKER | FY 2024-25 | Company Name
A2: 📋 Source: Recruitment Pipeline | Industry benchmark: >80% acceptance rate is healthy for IT companies
A3: 📌 SECTION A - OFFER LOG (ALL EXTENDED OFFERS)
A4: Rec ID | B4: Candidate Name | C4: Role | D4: Department | E4: Offer Date | F4: CTC Offered (INR LPA) | G4: Offer Accepted? | H4: Reason if Declined | I4: Joining Date | J4: Source | K4: Notes
A5: REC001 | B5: Arjun Mehta | C5: Senior Backend Engineer | D5: Engineering | E5: 45682 | F5: 18.5 | G5: Yes | H5: - | I5: 45689 | J5: LinkedIn | K5: Joined
A6: REC002 | B6: Sneha Rao | C6: Data Analyst | D6: Analytics | E6: 45687 | F6: 12 | G6: Yes | H6: - | I6: 45698 | J6: Naukri | K6: Joined
A7: REC005 | B7: Ravi Gupta | C7: QA Engineer | D7: Quality Assurance | E7: 45693 | F7: 10.5 | G7: Yes | H7: - | I7: 45703 | J7: Indeed | K7: Joined
A8: REC006 | B8: Ananya Singh | C8: UX Designer | D8: Design | E8: 45708 | F8: 14 | G8: Yes | H8: - | J8: Dribbble | K8: Offer accepted; joining pending
A9: REC011 | B9: Rohit Verma | C9: Senior Frontend Engineer | D9: Engineering | E9: 45710 | F9: 20 | G9: Yes | H9: - | I9: 45717 | J9: LinkedIn | K9: Joined
A10: REC012 | B10: Divya Krishnaswamy | C10: Scrum Master | D10: Product | E10: 45708 | F10: 16 | G10: No | H10: Accepted counter-offer from current employer | J10: Naukri | K10: Lost to counter-offer
A11: REC015 | B11: Ashwin Kumar | C11: Security Engineer | D11: Infrastructure | E11: 45720 | F11: 22 | G11: Yes | H11: - | I11: 45731 | J11: Referral (Internal) | K11: Joined
A12: REC018 | B12: Rekha Sundaram | C12: Customer Success Manager | D12: Sales | E12: 45734 | F12: 13.5 | G12: Yes | H12: - | J12: LinkedIn | K12: Joining confirmation pending
A13: REC004 | B13: Pooja Krishnan | C13: Product Manager | D13: Product | G13: Pending | H13: - | J13: LinkedIn | K13: Final round done; offer in preparation
A14: REC013 | B14: Sanjay Thakur | C14: ML Engineer | D14: AI/ML | G14: Pending | H14: - | J14: LinkedIn | K14: Technical round ongoing
A16: 📌 SECTION B - OFFER ACCEPTANCE KPIs
A17: Metric | B17: Value | C17: Benchmark | D17: Status | E17: Insight
A18: Total Offers Extended | B18: =COUNTIF(G5:G14,"Yes")+COUNTIF(G5:G14,"No")+COUNTIF(G5:G14,"Pending") -> 10 | C18: - | D18: - | E18: Excludes pending final rounds
A19: Offers Accepted | B19: =COUNTIF(G5:G14,"Yes") -> 7 | C19: - | D19: - | E19: Confirmed joins only
A20: Offers Declined | B20: =COUNTIF(G5:G14,"No") -> 1 | C20: - | D20: - | E20: Counter-offers main reason
A21: Acceptance Rate | B21: =IFERROR(COUNTIF(G5:G14,"Yes")/(COUNTIF(G5:G14,"Yes")+COUNTIF(G5:G14,"No")),0) -> 0.875 | C21: >80% | D21: =IF(B22>=0.8,"✅ Healthy","⚠️ Below benchmark") -> ✅ Healthy | E21: Excl. pending offers
A22: Avg. CTC Offered (LPA) | B22: =IFERROR(AVERAGEIF(G5:G14,"Yes",F5:F14),0) -> 15.785714 | C22: - | D22: - | E22: Accepted offers only
